Workbook

Sheet يناير
B9: سلطنة عمان
B10: وزارة الزراعة والثروة السمكية
B13: تقرير أعمال قسم الحجر البيطري لشهر يناير
B14: منفـــــــــــــــــــــــــــــــــذ: | D14: الوجاجه
B16: أولا: الواردات
B18: 1- حيوانــــــــــــات حيـــــــــــــة :
B19: م | C19: نوع الحيوان | D19: الوحدة | E19: العدد
B20: 1 | C20: ابقار | D20: راس | E20: 0
B21: 2 | C21: ابل | D21: راس | E21: 0
B22: 3 | C22: ضان | D22: راس | E22: 0
B23: 4 | C23: ماعز | D23: راس | E23: 0
B24: 5 | C24: خيول | D24: راس | E24: 18
B25: 6 | C25: بوني | D25: راس | E25: 0
B26: 7 | C26: زيبرا | D26: راس | E26: 0
B27: الإجمالي | E27: =SUM(E20:E26) -> 18
B29: م | C29: البلاد المصدرة :
B30: 1
B31: 2
B32: 3
B33: 4
B34: 5 | C34: الامارات/فرنسا/الولايات المتحدة/اورغواي/المملكة المتحدة و ايرلندا
B35: 6
B36: 7
B40: 2-حيوانــــــــــــات أليفة وبرية :
B41: م | C41: نوع الحيوان | D41: الوحدة | E41: العدد
B42: 1 | C42: كلاب | D42: راس | E42: 3
B43: 2 | C43: قطط | D43: راس | E43: 1
B44: 3 | C44: غزلان | D44: راس | E44: 0
B45: 4 | C45: المها العربية | D45: راس | E45: 0
B46: 5 | C46: اللاما | D46: راس | E46: 0
B47: 6 | C47: قوارض (فئران - سناجب - خنزيرغينيا - هامستر ) | D47: راس | E47: 0
B48: 7 | C48: سناجب | D48: راس | E48: 0
B49: 8 | C49: برمائيات (سلاحف - ضفادع ) | D49: راس | E49: 0
B50: 9 | C50: زواحف ( ثعابين - سحالي - تماسيح ) | D50: راس | E50: 0
B51: 10 | C51: حيوانات برية مفترسة | D51: راس | E51: 0
B52: 11 | C52: الرئيسيات | D52: راس | E52: 0
B53: 12 | C53: حيوانات السيرك والعروض | D53: راس | E53: 0
B54: الإجمالي | E54: =SUM(E42:E53) -> 4
B56: م | C56: البلاد المصدرة :
B57: 1 | C57: الامارات - قطر
...

Sheet فبراير
B9: سلطنة عمان
B10: وزارة الزراعة والثروة السمكية
B13: تقرير أعمال قسم الحجر البيطري لشهر فبراير
B14: منفــــــــــــــــــــــــــــــذ: | D14: =يناير!D14 -> الوجاجه
B16: أولا: الواردات
B18: 1- حيوانــــــــــــات حيـــــــــــــة :
B19: م | C19: نوع الحيوان | D19: الوحدة | E19: العدد
B20: 1 | C20: ابقار | D20: راس
B21: 2 | C21: ابل | D21: راس
B22: 3 | C22: ضان | D22: راس
B23: 4 | C23: ماعز | D23: راس
B24: 5 | C24: خيول | D24: راس | E24: 24
B25: 6 | C25: بوني | D25: راس
B26: 7 | C26: زيبرا | D26: راس
B27: الإجمالي | E27: =SUM(E20:E26) -> 24
B29: م | C29: البلاد المصدرة :
B30: 1
B31: 2
B32: 3
B33: 4
B34: 5 | C34: بريطانيا – فرنسا – بلجيكا – الدنمارك – عمان - الامارات
B35: 6
B36: 7
B40: 2-حيوانــــــــــــات أليفة وبرية :
B41: م | C41: نوع الحيوان | D41: الوحدة | E41: العدد
B42: 1 | C42: كلاب | D42: راس
B43: 2 | C43: قطط | D43: راس | E43: 1
B44: 3 | C44: غزلان | D44: راس
B45: 4 | C45: المها العربية | D45: راس
B46: 5 | C46: اللاما | D46: راس
B47: 6 | C47: قوارض (فئران - سناجب - خنزيرغينيا - هامستر ) | D47: راس
B48: 7 | C48: سناجب | D48: راس
B49: 8 | C49: برمائيات (سلاحف - ضفادع ) | D49: راس
B50: 9 | C50: زواحف ( ثعابين - سحالي - تماسيح ) | D50: راس
B51: 10 | C51: حيوانات برية مفترسة | D51: راس
B52: 11 | C52: الرئيسيات | D52: راس
B53: 12 | C53: حيوانات السيرك والعروض | D53: راس
B54: الإجمالي | E54: =SUM(E42:E53) -> 1
B56: م | C56: البلاد المصدرة :
B57: 1
...

Sheet مارس
B9: سلطنة عمان
B10: وزارة الزراعة والثروة السمكية
B13: تقرير أعمال قسم الحجر البيطري لشهر مارس
B14: منفــــــــــــــــــــــــــــــذ: | D14: =يناير!D14 -> الوجاجه
B16: أولا: الواردات
B18: 1- حيوانــــــــــــات حيـــــــــــــة :
B19: م | C19: نوع الحيوان | D19: الوحدة | E19: العدد
B20: 1 | C20: ابقار | D20: راس | E20: 0
B21: 2 | C21: ابل | D21: راس | E21: 0
B22: 3 | C22: ضان | D22: راس | E22: 0
B23: 4 | C23: ماعز | D23: راس | E23: 0
B24: 5 | C24: خيول | D24: راس | E24: 44
B25: 6 | C25: بوني | D25: راس | E25: 0
B26: 7 | C26: زيبرا | D26: راس | E26: 0
B27: الإجمالي | E27: =SUM(E20:E26) -> 44
B29: م | C29: البلاد المصدرة :
B30: 1
B31: 2
B32: 3
B33: 4
B34: 5 | C34: استراليا/السعودية/فرنسا/ايطاليا/اسبانيا/ايرلندا/امريكا/المملكة المتحدة/جنوب افريقيا/عمان/الامارات
B35: 6
B36: 7
B40: 2-حيوانــــــــــــات أليفة وبرية :
B41: م | C41: نوع الحيوان | D41: الوحدة | E41: العدد
B42: 1 | C42: كلاب | D42: راس | E42: 0
B43: 2 | C43: قطط | D43: راس | E43: 1
B44: 3 | C44: غزلان | D44: راس | E44: 0
B45: 4 | C45: المها العربية | D45: راس | E45: 0
B46: 5 | C46: اللاما | D46: راس | E46: 0
B47: 6 | C47: قوارض (فئران - سناجب - خنزيرغينيا - هامستر ) | D47: راس | E47: 0
B48: 7 | C48: سناجب | D48: راس | E48: 0
B49: 8 | C49: برمائيات (سلاحف - ضفادع ) | D49: راس | E49: 0
B50: 9 | C50: زواحف ( ثعابين - سحالي - تماسيح ) | D50: راس | E50: 0
B51: 10 | C51: حيوانات برية مفترسة | D51: راس | E51: 0
B52: 11 | C52: الرئيسيات | D52: راس | E52: 0
B53: 12 | C53: حيوانات السيرك والعروض | D53: راس
B54: الإجمالي | E54: =SUM(E42:E53) -> 1
B56: م | C56: البلاد المصدرة :
B57: 1
...

Sheet ابريل
B9: سلطنة عمان
B10: وزارة الزراعة والثروة السمكية
B13: تقرير أعمال قسم الحجر البيطري لشهر ابريل
B14: منفــــــــــــــــــــــــــــــذ: | D14: =يناير!D14 -> الوجاجه
B16: أولا: الواردات
B18: 1- حيوانــــــــــــات حيـــــــــــــة :
B19: م | C19: نوع الحيوان | D19: الوحدة | E19: العدد
B20: 1 | C20: ابقار | D20: راس | E20: 0
B21: 2 | C21: ابل | D21: راس | E21: 0
B22: 3 | C22: ضان | D22: راس | E22: 0
B23: 4 | C23: ماعز | D23: راس | E23: 0
B24: 5 | C24: خيول | D24: راس | E24: 41
B25: 6 | C25: بوني | D25: راس | E25: 0
B26: 7 | C26: زيبرا | D26: راس | E26: 0
B27: الإجمالي | E27: =SUM(E20:E26) -> 41
B29: م | C29: البلاد المصدرة :
B30: 1
B31: 2
B32: 3
B33: 4
B34: 5 | C34: الامارات/فرنسا/الولايات المتحدة/اورغواي/المملكة المتحدة /ايطاليا/ ايرلندا
B35: 6
B36: 7
B40: 2-حيوانــــــــــــات أليفة وبرية :
B41: م | C41: نوع الحيوان | D41: الوحدة | E41: العدد
B42: 1 | C42: كلاب | D42: راس | E42: 0
B43: 2 | C43: قطط | D43: راس | E43: 3
B44: 3 | C44: غزلان | D44: راس | E44: 0
B45: 4 | C45: المها العربية | D45: راس | E45: 0
B46: 5 | C46: اللاما | D46: راس | E46: 0
B47: 6 | C47: قوارض (فئران - سناجب - خنزيرغينيا - هامستر ) | D47: راس | E47: 0
B48: 7 | C48: سناجب | D48: راس | E48: 0
B49: 8 | C49: برمائيات (سلاحف - ضفادع ) | D49: راس | E49: 0
B50: 9 | C50: زواحف ( ثعابين - سحالي - تماسيح ) | D50: راس | E50: 0
B51: 10 | C51: حيوانات برية مفترسة | D51: راس | E51: 0
B52: 11 | C52: الرئيسيات | D52: راس | E52: 0
B53: 12 | C53: حيوانات السيرك والعروض | D53: راس | E53: 0
B54: الإجمالي | E54: =SUM(E42:E53) -> 3
B56: م | C56: البلاد المصدرة :
B57: 1
...

Sheet مايو
B9: سلطنة عمان
B10: وزارة الزراعة والثروة السمكية
B13: تقرير أعمال قسم الحجر البيطري لشهر مايو
B14: منفــــــــــــــــــــــــــــــذ: | D14: =يناير!D14 -> الوجاجه
B16: أولا: الواردات
B18: 1- حيوانــــــــــــات حيـــــــــــــة :
B19: م | C19: نوع الحيوان | D19: الوحدة | E19: العدد
B20: 1 | C20: ابقار | D20: راس
B21: 2 | C21: ابل | D21: راس
B22: 3 | C22: ضان | D22: راس
B23: 4 | C23: ماعز | D23: راس
B24: 5 | C24: خيول | D24: راس | E24: 27
B25: 6 | C25: بوني | D25: راس
B26: 7 | C26: زيبرا | D26: راس
B27: الإجمالي | E27: =SUM(E20:E26) -> 27
B29: م | C29: البلاد المصدرة :
B30: 1
B31: 2
B32: 3
B33: 4
B34: 5 | C34: أمريكا-الارجواي-الامارات-ايرلندا-بريطانيا-عمان-فرنسا-قطر-هولندا
B35: 6
B36: 7
B40: 2-حيوانــــــــــــات أليفة وبرية :
B41: م | C41: نوع الحيوان | D41: الوحدة | E41: العدد
B42: 1 | C42: كلاب | D42: راس
B43: 2 | C43: قطط | D43: راس
B44: 3 | C44: غزلان | D44: راس
B45: 4 | C45: المها العربية | D45: راس
B46: 5 | C46: اللاما | D46: راس
B47: 6 | C47: قوارض (فئران - سناجب - خنزيرغينيا - هامستر ) | D47: راس
B48: 7 | C48: سناجب | D48: راس
B49: 8 | C49: برمائيات (سلاحف - ضفادع ) | D49: راس
B50: 9 | C50: زواحف ( ثعابين - سحالي - تماسيح ) | D50: راس
B51: 10 | C51: حيوانات برية مفترسة | D51: راس
B52: 11 | C52: الرئيسيات | D52: راس
B53: 12 | C53: حيوانات السيرك والعروض | D53: راس
B54: الإجمالي | E54: =SUM(E42:E53) -> 0
B56: م | C56: البلاد المصدرة :
B57: 1
...

Sheet يونيو
B9: سلطنة عمان
B10: وزارة الزراعة والثروة السمكية
B13: تقرير أعمال قسم الحجر البيطري لشهر يونيو
B14: منفــــــــــــــــــــــــــــــذ: | D14: =يناير!D14 -> الوجاجه
B16: أولا: الواردات
B18: 1- حيوانــــــــــــات حيـــــــــــــة :
B19: م | C19: نوع الحيوان | D19: الوحدة | E19: العدد
B20: 1 | C20: ابقار | D20: راس
B21: 2 | C21: ابل | D21: راس
B22: 3 | C22: ضان | D22: راس
B23: 4 | C23: ماعز | D23: راس
B24: 5 | C24: خيول | D24: راس | E24: 7
B25: 6 | C25: بوني | D25: راس
B26: 7 | C26: زيبرا | D26: راس
B27: الإجمالي | E27: =SUM(E20:E26) -> 7
B29: م | C29: البلاد المصدرة :
B30: 1
B31: 2
B32: 3
B33: 4
B34: 5 | C34: فرنسا-استراليا -امريكا -سولفينيا-الامارات-الاورجواي
B35: 6
B36: 7
B40: 2-حيوانــــــــــــات أليفة وبرية :
B41: م | C41: نوع الحيوان | D41: الوحدة | E41: العدد
B42: 1 | C42: كلاب | D42: راس | E42: 2
B43: 2 | C43: قطط | D43: راس | E43: 2
B44: 3 | C44: غزلان | D44: راس
B45: 4 | C45: المها العربية | D45: راس
B46: 5 | C46: اللاما | D46: راس
B47: 6 | C47: قوارض (فئران - سناجب - خنزيرغينيا - هامستر ) | D47: راس | E47: 20
B48: 7 | C48: سناجب | D48: راس
B49: 8 | C49: برمائيات (سلاحف - ضفادع ) | D49: راس
B50: 9 | C50: زواحف ( ثعابين - سحالي - تماسيح ) | D50: راس
B51: 10 | C51: حيوانات برية مفترسة | D51: راس
B52: 11 | C52: الرئيسيات | D52: راس
B53: 12 | C53: حيوانات السيرك والعروض | D53: راس
B54: الإجمالي | E54: =SUM(E42:E53) -> 24
B56: م | C56: البلاد المصدرة :
B57: 1 | C57: الامارات
...

Sheet يوليو
B9: سلطنة عمان
B10: وزارة الزراعة والثروة السمكية
B13: تقرير أعمال قسم الحجر البيطري لشهر يوليو
B14: منفــــــــــــــــــــــــــــــذ: | D14: =يناير!D14 -> الوجاجه
B16: أولا: الواردات
B18: 1- حيوانــــــــــــات حيـــــــــــــة :
B19: م | C19: نوع الحيوان | D19: الوحدة | E19: العدد
B20: 1 | C20: ابقار | D20: راس | E20: 0
B21: 2 | C21: ابل | D21: راس
B22: 3 | C22: ضان | D22: راس
B23: 4 | C23: ماعز | D23: راس
B24: 5 | C24: خيول | D24: راس
B25: 6 | C25: بوني | D25: راس
B26: 7 | C26: زيبرا | D26: راس
B27: الإجمالي | E27: =SUM(E20:E26) -> 0
B29: م | C29: البلاد المصدرة :
B30: 1
B31: 2
B32: 3
B33: 4
B34: 5
B35: 6
B36: 7
B40: 2-حيوانــــــــــــات أليفة وبرية :
B41: م | C41: نوع الحيوان | D41: الوحدة | E41: العدد
B42: 1 | C42: كلاب | D42: راس
B43: 2 | C43: قطط | D43: راس
B44: 3 | C44: غزلان | D44: راس
B45: 4 | C45: المها العربية | D45: راس
B46: 5 | C46: اللاما | D46: راس
B47: 6 | C47: قوارض (فئران - سناجب - خنزيرغينيا - هامستر ) | D47: راس
B48: 7 | C48: سناجب | D48: راس
B49: 8 | C49: برمائيات (سلاحف - ضفادع ) | D49: راس
B50: 9 | C50: زواحف ( ثعابين - سحالي - تماسيح ) | D50: راس
B51: 10 | C51: حيوانات برية مفترسة | D51: راس
B52: 11 | C52: الرئيسيات | D52: راس
B53: 12 | C53: حيوانات السيرك والعروض | D53: راس
B54: الإجمالي | E54: =SUM(E42:E53) -> 0
B56: م | C56: البلاد المصدرة :
B57: 1
...

Sheet اغسطس
B9: سلطنة عمان
B10: وزارة الزراعة والثروة السمكية
B13: تقرير أعمال قسم الحجر البيطري لشهر أغسطس
B14: منفــــــــــــــــــــــــــــــذ: | D14: =يناير!D14 -> الوجاجه
B16: أولا: الواردات
B18: 1- حيوانــــــــــــات حيـــــــــــــة :
B19: م | C19: نوع الحيوان | D19: الوحدة | E19: العدد
B20: 1 | C20: ابقار | D20: راس | E20: 0
B21: 2 | C21: ابل | D21: راس | E21: 0
B22: 3 | C22: ضان | D22: راس | E22: 0
B23: 4 | C23: ماعز | D23: راس | E23: 0
B24: 5 | C24: خيول | D24: راس | E24: 0
B25: 6 | C25: بوني | D25: راس | E25: 0
B26: 7 | C26: زيبرا | D26: راس | E26: 0
B27: الإجمالي | E27: =SUM(E20:E26) -> 0
B29: م | C29: البلاد المصدرة :
B30: 1
B31: 2
B32: 3
B33: 4
B34: 5
B35: 6
B36: 7
B40: 2-حيوانــــــــــــات أليفة وبرية :
B41: م | C41: نوع الحيوان | D41: الوحدة | E41: العدد
B42: 1 | C42: كلاب | D42: راس | E42: 0
B43: 2 | C43: قطط | D43: راس | E43: 0
B44: 3 | C44: غزلان | D44: راس | E44: 0
B45: 4 | C45: المها العربية | D45: راس | E45: 0
B46: 5 | C46: اللاما | D46: راس | E46: 0
B47: 6 | C47: قوارض (فئران - سناجب - خنزيرغينيا - هامستر ) | D47: راس | E47: 0
B48: 7 | C48: سناجب | D48: راس | E48: 0
B49: 8 | C49: برمائيات (سلاحف - ضفادع ) | D49: راس | E49: 0
B50: 9 | C50: زواحف ( ثعابين - سحالي - تماسيح ) | D50: راس | E50: 0
B51: 10 | C51: حيوانات برية مفترسة | D51: راس | E51: 0
B52: 11 | C52: الرئيسيات | D52: راس | E52: 0
B53: 12 | C53: حيوانات السيرك والعروض | D53: راس | E53: 0
B54: الإجمالي | E54: =SUM(E42:E53) -> 0
B56: م | C56: البلاد المصدرة :
B57: 1
...

Sheet سبتمبر
B9: سلطنة عمان
B10: وزارة الزراعة والثروة السمكية
B13: تقرير أعمال قسم الحجر البيطري لشهر سبتمبر
B14: منفــــــــــــــــــــــــــــــذ: | D14: =يناير!D14 -> الوجاجه
B16: أولا: الواردات
B18: 1- حيوانــــــــــــات حيـــــــــــــة :
B19: م | C19: نوع الحيوان | D19: الوحدة | E19: العدد
B20: 1 | C20: ابقار | D20: راس | E20: 0
B21: 2 | C21: ابل | D21: راس | E21: 0
B22: 3 | C22: ضان | D22: راس | E22: 0
B23: 4 | C23: ماعز | D23: راس | E23: 0
B24: 5 | C24: خيول | D24: راس | E24: 0
B25: 6 | C25: بوني | D25: راس | E25: 0
B26: 7 | C26: زيبرا | D26: راس | E26: 0
B27: الإجمالي | E27: =SUM(E20:E26) -> 0
B29: م | C29: البلاد المصدرة :
B30: 1
B31: 2
B32: 3
B33: 4
B34: 5
B35: 6
B36: 7
B40: 2-حيوانــــــــــــات أليفة وبرية :
B41: م | C41: نوع الحيوان | D41: الوحدة | E41: العدد
B42: 1 | C42: كلاب | D42: راس | E42: 0
B43: 2 | C43: قطط | D43: راس | E43: 0
B44: 3 | C44: غزلان | D44: راس | E44: 0
B45: 4 | C45: المها العربية | D45: راس | E45: 0
B46: 5 | C46: اللاما | D46: راس | E46: 0
B47: 6 | C47: قوارض (فئران - سناجب - خنزيرغينيا - هامستر ) | D47: راس | E47: 0
B48: 7 | C48: سناجب | D48: راس | E48: 0
B49: 8 | C49: برمائيات (سلاحف - ضفادع ) | D49: راس | E49: 0
B50: 9 | C50: زواحف ( ثعابين - سحالي - تماسيح ) | D50: راس | E50: 0
B51: 10 | C51: حيوانات برية مفترسة | D51: راس | E51: 0
B52: 11 | C52: الرئيسيات | D52: راس | E52: 0
B53: 12 | C53: حيوانات السيرك والعروض | D53: راس | E53: 0
B54: الإجمالي | E54: =SUM(E42:E53) -> 0
B56: م | C56: البلاد المصدرة :
B57: 1
...

Sheet اكتوبر 
B9: سلطنة عمان
B10: وزارة الزراعة والثروة السمكية
B13: تقرير أعمال قسم الحجر البيطري لشهر أكتوبر
B14: منفــــــــــــــــــــــــــــــذ: | D14: =يناير!D14 -> الوجاجه
B16: أولا: الواردات
B18: 1- حيوانــــــــــــات حيـــــــــــــة :
B19: م | C19: نوع الحيوان | D19: الوحدة | E19: العدد
B20: 1 | C20: ابقار | D20: راس | E20: 0
B21: 2 | C21: ابل | D21: راس | E21: 0
B22: 3 | C22: ضان | D22: راس | E22: 0
B23: 4 | C23: ماعز | D23: راس | E23: 0
B24: 5 | C24: خيول | D24: راس | E24: 0
B25: 6 | C25: بوني | D25: راس | E25: 0
B26: 7 | C26: زيبرا | D26: راس | E26: 0
B27: الإجمالي | E27: =SUM(E20:E26) -> 0
B29: م | C29: البلاد المصدرة :
B30: 1
B31: 2
B32: 3
B33: 4
B34: 5
B35: 6
B36: 7
B40: 2-حيوانــــــــــــات أليفة وبرية :
B41: م | C41: نوع الحيوان | D41: الوحدة | E41: العدد
B42: 1 | C42: كلاب | D42: راس | E42: 0
B43: 2 | C43: قطط | D43: راس | E43: 0
B44: 3 | C44: غزلان | D44: راس | E44: 0
B45: 4 | C45: المها العربية | D45: راس | E45: 0
B46: 5 | C46: اللاما | D46: راس | E46: 0
B47: 6 | C47: قوارض (فئران - سناجب - خنزيرغينيا - هامستر ) | D47: راس | E47: 0
B48: 7 | C48: سناجب | D48: راس | E48: 0
B49: 8 | C49: برمائيات (سلاحف - ضفادع ) | D49: راس | E49: 0
B50: 9 | C50: زواحف ( ثعابين - سحالي - تماسيح ) | D50: راس | E50: 0
B51: 10 | C51: حيوانات برية مفترسة | D51: راس | E51: 0
B52: 11 | C52: الرئيسيات | D52: راس | E52: 0
B53: 12 | C53: حيوانات السيرك والعروض | D53: راس | E53: 0
B54: الإجمالي | E54: =SUM(E42:E53) -> 0
B56: م | C56: البلاد المصدرة :
B57: 1
...

Sheet نوفمبر
B9: سلطنة عمان
B10: وزارة الزراعة والثروة السمكية
B13: تقرير أعمال قسم الحجر البيطري لشهر نوفمبر
B14: منفــــــــــــــــــــــــــــــذ: | D14: =يناير!D14 -> الوجاجه
B16: أولا: الواردات
B18: 1- حيوانــــــــــــات حيـــــــــــــة :
B19: م | C19: نوع الحيوان | D19: الوحدة | E19: العدد
B20: 1 | C20: ابقار | D20: راس | E20: 0
B21: 2 | C21: ابل | D21: راس | E21: 0
B22: 3 | C22: ضان | D22: راس | E22: 0
B23: 4 | C23: ماعز | D23: راس | E23: 0
B24: 5 | C24: خيول | D24: راس | E24: 0
B25: 6 | C25: بوني | D25: راس | E25: 0
B26: 7 | C26: زيبرا | D26: راس | E26: 0
B27: الإجمالي | E27: =SUM(E20:E26) -> 0
B29: م | C29: البلاد المصدرة :
B30: 1
B31: 2
B32: 3
B33: 4
B34: 5
B35: 6
B36: 7
B40: 2-حيوانــــــــــــات أليفة وبرية :
B41: م | C41: نوع الحيوان | D41: الوحدة | E41: العدد
B42: 1 | C42: كلاب | D42: راس
B43: 2 | C43: قطط | D43: راس
B44: 3 | C44: غزلان | D44: راس
B45: 4 | C45: المها العربية | D45: راس
B46: 5 | C46: اللاما | D46: راس
B47: 6 | C47: قوارض (فئران - سناجب - خنزيرغينيا - هامستر ) | D47: راس
B48: 7 | C48: سناجب | D48: راس
B49: 8 | C49: برمائيات (سلاحف - ضفادع ) | D49: راس
B50: 9 | C50: زواحف ( ثعابين - سحالي - تماسيح ) | D50: راس
B51: 10 | C51: حيوانات برية مفترسة | D51: راس
B52: 11 | C52: الرئيسيات | D52: راس
B53: 12 | C53: حيوانات السيرك والعروض | D53: راس
B54: الإجمالي | E54: =SUM(E42:E53) -> 0
B56: م | C56: البلاد المصدرة :
B57: 1
...

Sheet ديسمبر
B9: سلطنة عمان
B10: وزارة الزراعة والثروة السمكية
B13: تقرير أعمال قسم الحجر البيطري لشهر ديسمبر
B14: منفــــــــــــــــــــــــــــــذ: | D14: =يناير!D14 -> الوجاجه
B16: أولا: الواردات
B18: 1- حيوانــــــــــــات حيـــــــــــــة :
B19: م | C19: نوع الحيوان | D19: الوحدة | E19: العدد
B20: 1 | C20: ابقار | D20: راس
B21: 2 | C21: ابل | D21: راس
B22: 3 | C22: ضان | D22: راس
B23: 4 | C23: ماعز | D23: راس
B24: 5 | C24: خيول | D24: راس
B25: 6 | C25: بوني | D25: راس
B26: 7 | C26: زيبرا | D26: راس
B27: الإجمالي | E27: =SUM(E20:E26) -> 0
B29: م | C29: البلاد المصدرة :
B30: 1
B31: 2
B32: 3
B33: 4
B34: 5
B35: 6
B36: 7
B40: 2-حيوانــــــــــــات أليفة وبرية :
B41: م | C41: نوع الحيوان | D41: الوحدة | E41: العدد
B42: 1 | C42: كلاب | D42: راس
B43: 2 | C43: قطط | D43: راس
B44: 3 | C44: غزلان | D44: راس
B45: 4 | C45: المها العربية | D45: راس
B46: 5 | C46: اللاما | D46: راس
B47: 6 | C47: قوارض (فئران - سناجب - خنزيرغينيا - هامستر ) | D47: راس
B48: 7 | C48: سناجب | D48: راس
B49: 8 | C49: برمائيات (سلاحف - ضفادع ) | D49: راس
B50: 9 | C50: زواحف ( ثعابين - سحالي - تماسيح ) | D50: راس
B51: 10 | C51: حيوانات برية مفترسة | D51: راس
B52: 11 | C52: الرئيسيات | D52: راس
B53: 12 | C53: حيوانات السيرك والعروض | D53: راس
B54: الإجمالي | E54: =SUM(E42:E53) -> 0
B56: م | C56: البلاد المصدرة :
B57: 1
...

Sheet التقرير السنوي
B9: سلطنة عمان
B10: وزارة الزراعة والثروة السمكية
B13: التقرير السنوي لأعمال قسم الحجر البيطري
B14: منفـــــــــــــــــــــــــــــــــذ: | D14: =يناير!D14 -> الوجاجه
B16: أولا: الواردات
B18: 1- حيوانــــــــــــات حيـــــــــــــة :
B19: م | C19: نوع الحيوان | D19: الوحدة | E19: العدد
B20: 1 | C20: ابقار | D20: راس | E20: =ديسمبر!E20+نوفمبر!E20+'اكتوبر '!E20+سبتمبر!E20+اغسطس!E20+يوليو!E20+يونيو!E20+مايو!E20+ابريل!E20+مارس!E20+فبراير!E20+يناير!E20 -> 0
B21: 2 | C21: ابل | D21: راس | E21: =ديسمبر!E21+نوفمبر!E21+'اكتوبر '!E21+سبتمبر!E21+اغسطس!E21+يوليو!E21+يونيو!E21+مايو!E21+ابريل!E21+مارس!E21+فبراير!E21+يناير!E21 -> 0
B22: 3 | C22: ضان | D22: راس | E22: =ديسمبر!E22+نوفمبر!E22+'اكتوبر '!E22+سبتمبر!E22+اغسطس!E22+يوليو!E22+يونيو!E22+مايو!E22+ابريل!E22+مارس!E22+فبراير!E22+يناير!E22 -> 0
B23: 4 | C23: ماعز | D23: راس | E23: =ديسمبر!E23+نوفمبر!E23+'اكتوبر '!E23+سبتمبر!E23+اغسطس!E23+يوليو!E23+يونيو!E23+مايو!E23+ابريل!E23+مارس!E23+فبراير!E23+يناير!E23 -> 0
B24: 5 | C24: خيول | D24: راس | E24: =ديسمبر!E24+نوفمبر!E24+'اكتوبر '!E24+سبتمبر!E24+اغسطس!E24+يوليو!E24+يونيو!E24+مايو!E24+ابريل!E24+مارس!E24+فبراير!E24+يناير!E24 -> 161
B25: 6 | C25: بوني | D25: راس | E25: =ديسمبر!E25+نوفمبر!E25+'اكتوبر '!E25+سبتمبر!E25+اغسطس!E25+يوليو!E25+يونيو!E25+مايو!E25+ابريل!E25+مارس!E25+فبراير!E25+يناير!E25 -> 0
B26: 7 | C26: زيبرا | D26: راس | E26: =ديسمبر!E26+نوفمبر!E26+'اكتوبر '!E26+سبتمبر!E26+اغسطس!E26+يوليو!E26+يونيو!E26+مايو!E26+ابريل!E26+مارس!E26+فبراير!E26+يناير!E26 -> 0
B27: الإجمالي | E27: =SUM(E20:E26) -> 161
B29: م | C29: البلاد المصدرة :
B30: 1 | C30: =CONCATENATE(يناير!C30,فبراير!C30,مارس!C30,ابريل!C30,مايو!C30,يونيو!C30,يوليو!C30,اغسطس!C30,سبتمبر!C30,نوفمبر!C30,'اكتوبر '!C30:G30,ديسمبر!C30)
B31: 2 | C31: =CONCATENATE(يناير!C31,فبراير!C31,مارس!C31,ابريل!C31,مايو!C31,يونيو!C31,يوليو!C31,اغسطس!C31,سبتمبر!C31,نوفمبر!C31,'اكتوبر '!C31:G31,ديسمبر!C31)
B32: 3 | C32: =CONCATENATE(يناير!C32,فبراير!C32,مارس!C32,ابريل!C32,مايو!C32,يونيو!C32,يوليو!C32,اغسطس!C32,سبتمبر!C32,نوفمبر!C32,'اكتوبر '!C32:G32,ديسمبر!C32)
B33: 4 | C33: =CONCATENATE(يناير!C33,فبراير!C33,مارس!C33,ابريل!C33,مايو!C33,يونيو!C33,يوليو!C33,اغسطس!C33,سبتمبر!C33,نوفمبر!C33,'اكتوبر '!C33:G33,ديسمبر!C33)
B34: 5 | C34: =CONCATENATE(يناير!C34,فبراير!C34,مارس!C34,ابريل!C34,مايو!C34,يونيو!C34,يوليو!C34,اغسطس!C34,سبتمبر!C34,نوفمبر!C34,'اكتوبر '!C34:G34,ديسمبر!C34) -> الامارات/فرنسا/الولايات المتحدة/اورغواي/المملكة المتحدة و ايرلندابريطانيا – فرنسا – بلجيكا – الدنمارك – عمان - الاماراتاستراليا/السعودية/فرنسا/ايطاليا/اسبانيا/ايرلندا/امريكا/المملكة المتحدة/جنوب افريقيا/عمان/الاماراتالامارات/فرنسا/الولايات المتحدة/اورغواي/المملكة المتحدة /ايطاليا/ ايرلنداأمريكا-الارجواي-الامارات-ايرلندا-بريطانيا-عمان-فرنسا-قطر-هولندافرنسا-استراليا -امريكا -سولفينيا-الامارات-الاورجواي
B35: 6 | C35: =CONCATENATE(يناير!C35,فبراير!C35,مارس!C35,ابريل!C35,مايو!C35,يونيو!C35,يوليو!C35,اغسطس!C35,سبتمبر!C35,نوفمبر!C35,'اكتوبر '!C35:G35,ديسمبر!C35)
B36: 7 | C36: =CONCATENATE(يناير!C36,فبراير!C36,مارس!C36,ابريل!C36,مايو!C36,يونيو!C36,يوليو!C36,اغسطس!C36,سبتمبر!C36,نوفمبر!C36,'اكتوبر '!C36:G36,ديسمبر!C36)
B40: 2-حيوانــــــــــــات أليفة وبرية :
B41: م | C41: نوع الحيوان | D41: الوحدة | E41: العدد
B42: 1 | C42: كلاب | D42: راس | E42: =ديسمبر!E42+نوفمبر!E42+'اكتوبر '!E42+سبتمبر!E42+اغسطس!E42+يوليو!E42+يونيو!E42+مايو!E42+ابريل!E42+مارس!E42+فبراير!E42+يناير!E42 -> 5
B43: 2 | C43: قطط | D43: راس | E43: =ديسمبر!E43+نوفمبر!E43+'اكتوبر '!E43+سبتمبر!E43+اغسطس!E43+يوليو!E43+يونيو!E43+مايو!E43+ابريل!E43+مارس!E43+فبراير!E43+يناير!E43 -> 8
B44: 3 | C44: غزلان | D44: راس | E44: =ديسمبر!E44+نوفمبر!E44+'اكتوبر '!E44+سبتمبر!E44+اغسطس!E44+يوليو!E44+يونيو!E44+مايو!E44+ابريل!E44+مارس!E44+فبراير!E44+يناير!E44 -> 0
B45: 4 | C45: المها العربية | D45: راس | E45: =ديسمبر!E45+نوفمبر!E45+'اكتوبر '!E45+سبتمبر!E45+اغسطس!E45+يوليو!E45+يونيو!E45+مايو!E45+ابريل!E45+مارس!E45+فبراير!E45+يناير!E45 -> 0
B46: 5 | C46: اللاما | D46: راس | E46: =ديسمبر!E46+نوفمبر!E46+'اكتوبر '!E46+سبتمبر!E46+اغسطس!E46+يوليو!E46+يونيو!E46+مايو!E46+ابريل!E46+مارس!E46+فبراير!E46+يناير!E46 -> 0
B47: 6 | C47: قوارض (فئران - سناجب - خنزيرغينيا - هامستر ) | D47: راس | E47: =ديسمبر!E47+نوفمبر!E47+'اكتوبر '!E47+سبتمبر!E47+اغسطس!E47+يوليو!E47+يونيو!E47+مايو!E47+ابريل!E47+مارس!E47+فبراير!E47+يناير!E47 -> 20
B48: 7 | C48: سناجب | D48: راس | E48: =ديسمبر!E48+نوفمبر!E48+'اكتوبر '!E48+سبتمبر!E48+اغسطس!E48+يوليو!E48+يونيو!E48+مايو!E48+ابريل!E48+مارس!E48+فبراير!E48+يناير!E48 -> 0
B49: 8 | C49: برمائيات (سلاحف - ضفادع ) | D49: راس | E49: =ديسمبر!E49+نوفمبر!E49+'اكتوبر '!E49+سبتمبر!E49+اغسطس!E49+يوليو!E49+يونيو!E49+مايو!E49+ابريل!E49+مارس!E49+فبراير!E49+يناير!E49 -> 0
B50: 9 | C50: زواحف ( ثعابين - سحالي - تماسيح ) | D50: راس | E50: =ديسمبر!E50+نوفمبر!E50+'اكتوبر '!E50+سبتمبر!E50+اغسطس!E50+يوليو!E50+يونيو!E50+مايو!E50+ابريل!E50+مارس!E50+فبراير!E50+يناير!E50 -> 0
B51: 10 | C51: حيوانات برية مفترسة | D51: راس | E51: =ديسمبر!E51+نوفمبر!E51+'اكتوبر '!E51+سبتمبر!E51+اغسطس!E51+يوليو!E51+يونيو!E51+مايو!E51+ابريل!E51+مارس!E51+فبراير!E51+يناير!E51 -> 0
B52: 11 | C52: الرئيسيات | D52: راس | E52: =ديسمبر!E52+نوفمبر!E52+'اكتوبر '!E52+سبتمبر!E52+اغسطس!E52+يوليو!E52+يونيو!E52+مايو!E52+ابريل!E52+مارس!E52+فبراير!E52+يناير!E52 -> 0
B53: 12 | C53: حيوانات السيرك والعروض | D53: راس | E53: =ديسمبر!E53+نوفمبر!E53+'اكتوبر '!E53+سبتمبر!E53+اغسطس!E53+يوليو!E53+يونيو!E53+مايو!E53+ابريل!E53+مارس!E53+فبراير!E53+يناير!E53 -> 0
B54: الإجمالي | E54: =SUM(E42:E53) -> 33
B56: م | C56: البلاد المصدرة :
B57: 1 | C57: =CONCATENATE(يناير!C57,فبراير!C57,مارس!C57,ابريل!C57,مايو!C57,يونيو!C57,يوليو!C57,اغسطس!C57,سبتمبر!C57,نوفمبر!C57,'اكتوبر '!C57:G57,ديسمبر!C57) -> الامارات - قطرالامارات
...
